<!-- Wheeled UR5e HYBRID: 4-DOF kinematic base + 6-DOF dynamic arm (Phase 4).

     Base DOFs: base_x, base_y, base_z, base_yaw (velocity-controlled via position actuators)
     Arm DOFs: shoulder_pan, shoulder_lift, elbow, wrist_1, wrist_2, wrist_3 (torque-controlled)

     Key differences from wheeled_ur5e.xml:
     - Base actuators: still <position> (driven by integrated MPC velocity commands)
     - Arm actuators: <motor> (direct torque control from MPC)
     - State space: [q_base(4), q_arm(6), v_arm(6)] = 16-dim
     - Control space: [v_base(4), tau_arm(6)] = 10-dim
-->
<mujoco model="wheeled_ur5e_hybrid">
  <compiler angle="radian" autolimits="true"/>

  <option timestep="0.002" integrator="implicitfast" gravity="0 0 -9.81"/>

  <!-- Rendering: soft headlight off, use explicit lights; shadows + nicer quality -->
  <visual>
    <headlight diffuse="0.6 0.6 0.6" ambient="0.3 0.3 0.3" specular="0 0 0"/>
    <rgba haze="0.15 0.25 0.35 1"/>
    <global azimuth="120" elevation="-20"/>
    <quality shadowsize="4096"/>
    <map force="0.1" zfar="30"/>
  </visual>

  <!-- Scene assets: gradient skybox + checkered ground plane -->
  <asset>
    <texture type="skybox" builtin="gradient" rgb1="0.3 0.5 0.7" rgb2="0 0 0"
             width="512" height="3072"/>
    <texture type="2d" name="groundplane" builtin="checker" mark="edge"
             rgb1="0.2 0.3 0.4" rgb2="0.1 0.2 0.3" markrgb="0.8 0.8 0.8"
             width="300" height="300"/>
    <material name="groundplane" texture="groundplane" texuniform="true"
              texrepeat="5 5" reflectance="0.2"/>
  </asset>

  <default>
    <joint limited="true"/>
    <geom contype="0" conaffinity="0" condim="1" solref="0.008 1"/>
    <position kp="400" kv="40" ctrllimited="true"/>
    <!-- Motor defaults: typical UR5e joint torque limits -->
    <motor ctrllimited="true" ctrlrange="-150 150"/>
  </default>

  <worldbody>

    <!-- Scene lighting and ground -->
    <light pos="0 0 3.5" dir="0 0 -1" directional="true"
           diffuse="0.4 0.4 0.4" specular="0.1 0.1 0.1"/>
    <light pos="1.5 1.5 2.5" dir="-1 -1 -1.5" diffuse="0.5 0.5 0.5"/>
    <geom name="floor" type="plane" size="0 0 0.05" pos="0 0 0"
          material="groundplane"/>

    <!-- Target marker: mocap body for visualizing desired end-effector position -->
    <body name="target_body" mocap="true" pos="0.62 0.06 0.86">
      <site name="target_site" type="sphere" size="0.020" rgba="1 0.5 0 0.8"/>
    </body>

    <!-- Virtual mobile base (same structure as wheeled_ur5e.xml) -->
    <body name="base_x_body" pos="0 0 0">
      <inertial pos="0 0 0" mass="2.0" diaginertia="0.1 0.1 0.1"/>
      <joint name="base_x" type="slide" axis="1 0 0" range="-3.0 3.0" damping="10.0"/>

      <body name="base_y_body">
        <inertial pos="0 0 0" mass="2.0" diaginertia="0.1 0.1 0.1"/>
        <joint name="base_y" type="slide" axis="0 1 0" range="-3.0 3.0" damping="10.0"/>

        <body name="base_yaw_body">
          <inertial pos="0 0 0" mass="2.0" diaginertia="0.1 0.1 0.1"/>
          <joint name="base_yaw" type="hinge" axis="0 0 1" range="-3.1416 3.1416" damping="5.0"/>

          <!-- Chassis + wheels -->
          <body name="chassis" pos="0 0 0.14">
            <geom type="box" size="0.35 0.25 0.05" pos="0 0 0" rgba="0.2 0.2 0.7 1" mass="20.0"/>
            <geom type="cylinder" size="0.1 0.04" pos=" 0.25  0.22 -0.04"
                  euler="1.5708 0 0" rgba="0.1 0.1 0.1 1" mass="1.0"/>
            <geom type="cylinder" size="0.1 0.04" pos=" 0.25 -0.22 -0.04"
                  euler="1.5708 0 0" rgba="0.1 0.1 0.1 1" mass="1.0"/>
            <geom type="cylinder" size="0.1 0.04" pos="-0.25  0.22 -0.04"
                  euler="1.5708 0 0" rgba="0.1 0.1 0.1 1" mass="1.0"/>
            <geom type="cylinder" size="0.1 0.04" pos="-0.25 -0.22 -0.04"
                  euler="1.5708 0 0" rgba="0.1 0.1 0.1 1" mass="1.0"/>
          </body>

          <!-- Lift stage -->
          <body name="base_z_body" pos="0 0 0">
            <inertial pos="0 0 0.1" mass="2.0" diaginertia="0.05 0.05 0.05"/>
            <joint name="base_z" type="slide" axis="0 0 1" range="0.0 0.5" damping="10.0"/>
            <geom type="cylinder" size="0.045 0.135" pos="0 0 0.135"
                  rgba="0.5 0.5 0.5 1" mass="2.0"/>

            <!-- UR5e arm -->
            <include file="ur5e/ur5e_kinematics.xml"/>
          </body>

        </body>
      </body>
    </body>

  </worldbody>

  <actuator>
    <!-- Base: position actuators (velocity-controlled via integrated commands) -->
    <position name="act_base_x"     joint="base_x"             kp="2000" kv="200"
              ctrlrange="-3.0 3.0"/>
    <position name="act_base_y"     joint="base_y"             kp="2000" kv="200"
              ctrlrange="-3.0 3.0"/>
    <position name="act_base_z"     joint="base_z"             kp="35000" kv="800"
              ctrlrange="0.0 0.5"/>
    <position name="act_base_yaw"   joint="base_yaw"           kp="2000" kv="200"
              ctrlrange="-3.1416 3.1416"/>

    <!-- Arm: motor actuators (direct torque control) -->
    <!-- UR5e typical joint torque limits: shoulder ~150 Nm, elbow ~150 Nm, wrist ~28 Nm -->
    <motor name="act_shoulder_pan"   joint="shoulder_pan_joint"   ctrlrange="-150 150" gear="1"/>
    <motor name="act_shoulder_lift"  joint="shoulder_lift_joint"  ctrlrange="-150 150" gear="1"/>
    <motor name="act_elbow"          joint="elbow_joint"          ctrlrange="-150 150" gear="1"/>
    <motor name="act_wrist_1"        joint="wrist_1_joint"        ctrlrange="-28 28" gear="1"/>
    <motor name="act_wrist_2"        joint="wrist_2_joint"        ctrlrange="-28 28" gear="1"/>
    <motor name="act_wrist_3"        joint="wrist_3_joint"        ctrlrange="-28 28" gear="1"/>
  </actuator>

</mujoco>
