<mujoco model="wheeled_dual_ur5e_v2">
  <compiler angle="radian"/>

  <option integrator="implicitfast"/>

  <size nkey="1"/>

  <visual>
    <global azimuth="125" elevation="-18"/>
    <headlight ambient="0.3 0.3 0.3" diffuse="0.6 0.6 0.6" specular="0 0 0"/>
    <map force="0.1" zfar="30"/>
    <rgba haze="0.15 0.25 0.35 1"/>
  </visual>

  <default>
    <joint limited="true"/>
    <geom contype="0" conaffinity="0" condim="1" solref="0.008"/>
    <general ctrllimited="true" biastype="affine" gainprm="400" biasprm="0 -400 -40"/>
    <default class="ur5e">
      <material shininess="0.25"/>
      <joint range="-6.28319 6.28319" armature="0.1"/>
      <site size="0.001 0.005 0.005" group="4" rgba="0.5 0.5 0.5 0.3"/>
      <general ctrlrange="-6.2831 6.2831" forcerange="-150 150" gainprm="2000" biasprm="0 -2000 -400"/>
      <default class="size3">
        <default class="size3_limited">
          <joint range="-3.1415 3.1415"/>
          <general ctrlrange="-3.1415 3.1415"/>
        </default>
      </default>
      <default class="size1">
        <general forcerange="-28 28" gainprm="500" biasprm="0 -500 -100"/>
      </default>
      <default class="visual">
        <geom type="mesh" group="2"/>
      </default>
      <default class="collision">
        <geom type="capsule" group="3"/>
        <default class="eef_collision">
          <geom type="cylinder"/>
        </default>
      </default>
    </default>
  </default>

  <asset>
    <texture type="skybox" colorspace="auto" builtin="gradient" rgb1="0.28 0.4 0.56" rgb2="0.02 0.03 0.05" width="512" height="3072"/>
    <texture type="2d" colorspace="auto" name="groundplane" builtin="checker" mark="edge" rgb1="0.22 0.25 0.28" rgb2="0.12 0.15 0.18" markrgb="0.75 0.75 0.75" width="300" height="300"/>
    <material name="groundplane" texture="groundplane" texuniform="true" texrepeat="6 6" reflectance="0.18"/>
    <material name="mat_base_dark" rgba="0.055 0.06 0.07 1"/>
    <material name="mat_base_panel" rgba="0.18 0.21 0.24 1"/>
    <material name="mat_base_blue" rgba="0.12 0.2 0.34 1"/>
    <material name="mat_rubber" rgba="0.015 0.015 0.015 1"/>
    <material name="mat_hub" rgba="0.55 0.57 0.58 1"/>
    <material name="mat_aluminum" rgba="0.62 0.64 0.66 1"/>
    <material name="mat_column" rgba="0.38 0.42 0.46 1"/>
    <material name="mat_accent" rgba="1 0.48 0.1 1"/>
    <material name="mat_left_arm" rgba="0.06 0.72 0.42 1"/>
    <material name="mat_left_arm_light" rgba="0.16 0.88 0.55 1"/>
    <material name="mat_right_arm" rgba="0.12 0.48 0.95 1"/>
    <material name="mat_right_arm_light" rgba="0.25 0.62 1 1"/>
    <material name="black" class="ur5e" rgba="0.033 0.033 0.033 1"/>
    <material name="jointgray" class="ur5e" rgba="0.278 0.278 0.278 1"/>
    <material name="linkgray" class="ur5e" rgba="0.82 0.82 0.82 1"/>
    <material name="urblue" class="ur5e" rgba="0.49 0.678 0.8 1"/>
    <mesh name="base_0" file="mujoco_menager/mujoco_menagerie/universal_robots_ur5e/assets/base_0.obj"/>
    <mesh name="base_1" file="mujoco_menager/mujoco_menagerie/universal_robots_ur5e/assets/base_1.obj"/>
    <mesh name="shoulder_0" file="mujoco_menager/mujoco_menagerie/universal_robots_ur5e/assets/shoulder_0.obj"/>
    <mesh name="shoulder_1" file="mujoco_menager/mujoco_menagerie/universal_robots_ur5e/assets/shoulder_1.obj"/>
    <mesh name="shoulder_2" file="mujoco_menager/mujoco_menagerie/universal_robots_ur5e/assets/shoulder_2.obj"/>
    <mesh name="upperarm_0" file="mujoco_menager/mujoco_menagerie/universal_robots_ur5e/assets/upperarm_0.obj"/>
    <mesh name="upperarm_1" file="mujoco_menager/mujoco_menagerie/universal_robots_ur5e/assets/upperarm_1.obj"/>
    <mesh name="upperarm_2" file="mujoco_menager/mujoco_menagerie/universal_robots_ur5e/assets/upperarm_2.obj"/>
    <mesh name="upperarm_3" file="mujoco_menager/mujoco_menagerie/universal_robots_ur5e/assets/upperarm_3.obj"/>
    <mesh name="forearm_0" file="mujoco_menager/mujoco_menagerie/universal_robots_ur5e/assets/forearm_0.obj"/>
    <mesh name="forearm_1" file="mujoco_menager/mujoco_menagerie/universal_robots_ur5e/assets/forearm_1.obj"/>
    <mesh name="forearm_2" file="mujoco_menager/mujoco_menagerie/universal_robots_ur5e/assets/forearm_2.obj"/>
    <mesh name="forearm_3" file="mujoco_menager/mujoco_menagerie/universal_robots_ur5e/assets/forearm_3.obj"/>
    <mesh name="wrist1_0" file="mujoco_menager/mujoco_menagerie/universal_robots_ur5e/assets/wrist1_0.obj"/>
    <mesh name="wrist1_1" file="mujoco_menager/mujoco_menagerie/universal_robots_ur5e/assets/wrist1_1.obj"/>
    <mesh name="wrist1_2" file="mujoco_menager/mujoco_menagerie/universal_robots_ur5e/assets/wrist1_2.obj"/>
    <mesh name="wrist2_0" file="mujoco_menager/mujoco_menagerie/universal_robots_ur5e/assets/wrist2_0.obj"/>
    <mesh name="wrist2_1" file="mujoco_menager/mujoco_menagerie/universal_robots_ur5e/assets/wrist2_1.obj"/>
    <mesh name="wrist2_2" file="mujoco_menager/mujoco_menagerie/universal_robots_ur5e/assets/wrist2_2.obj"/>
    <mesh name="wrist3" file="mujoco_menager/mujoco_menagerie/universal_robots_ur5e/assets/wrist3.obj"/>
  </asset>

  <worldbody>
    <geom name="floor" size="0 0 0.05" type="plane" contype="1" conaffinity="1" material="groundplane"/>
    <light pos="0 0 3.8" dir="0 0 -1" type="directional" diffuse="0.45 0.45 0.45" specular="0.1 0.1 0.1"/>
    <light pos="2 1.4 2.4" dir="-0.674882 -0.449921 -0.584898" diffuse="0.55 0.55 0.55"/>
    <body name="base_x_body">
      <inertial pos="0 0 0" mass="1" diaginertia="0.05 0.05 0.05"/>
      <joint name="base_x" pos="0 0 0" axis="1 0 0" type="slide" range="-3 3" damping="10"/>
      <body name="base_y_body">
        <inertial pos="0 0 0" mass="1" diaginertia="0.05 0.05 0.05"/>
        <joint name="base_y" pos="0 0 0" axis="0 1 0" type="slide" range="-3 3" damping="10"/>
        <body name="base_yaw_body">
          <inertial pos="0 0 0" mass="1" diaginertia="0.05 0.05 0.05"/>
          <joint name="base_yaw" pos="0 0 0" axis="0 0 1" range="-3.1416 3.1416" damping="5"/>
          <body name="mobile_base" pos="0 0 0.18">
            <inertial pos="0 0 0.02" mass="58" diaginertia="4 5 6"/>
            <geom size="0.58 0.4 0.07" type="box" mass="0" material="mat_base_dark"/>
            <geom size="0.52 0.34 0.035" pos="0.02 0 0.115" type="box" mass="0" material="mat_base_panel"/>
            <geom size="0.3 0.37 0.02" pos="0.19 0 0.165" type="box" mass="0" material="mat_base_blue"/>
            <geom size="0.24 0.3 0.02" pos="-0.24 0 0.158" type="box" mass="0" material="mat_base_panel"/>
            <geom size="0.025 0.39" pos="0.58 0 0.02" quat="0.707107 -0.707107 0 0" type="capsule" mass="0" material="mat_accent"/>
            <geom size="0.025 0.39" pos="-0.58 0 0.02" quat="0.707107 -0.707107 0 0" type="capsule" mass="0" material="mat_accent"/>
            <geom size="0.025 0.52" pos="0 0.43 0.02" quat="0.707107 0 -0.707107 0" type="capsule" mass="0" material="mat_accent"/>
            <geom size="0.025 0.52" pos="0 -0.43 0.02" quat="0.707107 0 -0.707107 0" type="capsule" mass="0" material="mat_accent"/>
            <geom size="0.06 0.035 0.26" pos="-0.12 0.16 0.4" type="box" mass="0" material="mat_column"/>
            <geom size="0.06 0.035 0.26" pos="-0.12 -0.16 0.4" type="box" mass="0" material="mat_column"/>
            <geom size="0.09 0.22 0.035" pos="-0.12 0 0.665" type="box" mass="0" material="mat_aluminum"/>
            <body name="front_left_wheel_module" pos="0.43 0.42 -0.05">
              <geom size="0.07 0.03 0.085" pos="0 -0.045 0.04" type="box" mass="0.8" material="mat_column"/>
              <geom size="0.13 0.055" quat="0.707105 0.707108 0 0" type="cylinder" mass="2.5" material="mat_rubber"/>
              <geom size="0.065 0.06" quat="0.707105 0.707108 0 0" type="cylinder" mass="0.5" material="mat_hub"/>
            </body>
            <body name="front_right_wheel_module" pos="0.43 -0.42 -0.05">
              <geom size="0.07 0.03 0.085" pos="0 0.045 0.04" type="box" mass="0.8" material="mat_column"/>
              <geom size="0.13 0.055" quat="0.707105 0.707108 0 0" type="cylinder" mass="2.5" material="mat_rubber"/>
              <geom size="0.065 0.06" quat="0.707105 0.707108 0 0" type="cylinder" mass="0.5" material="mat_hub"/>
            </body>
            <body name="rear_left_wheel_module" pos="-0.43 0.42 -0.05">
              <geom size="0.07 0.03 0.085" pos="0 -0.045 0.04" type="box" mass="0.8" material="mat_column"/>
              <geom size="0.13 0.055" quat="0.707105 0.707108 0 0" type="cylinder" mass="2.5" material="mat_rubber"/>
              <geom size="0.065 0.06" quat="0.707105 0.707108 0 0" type="cylinder" mass="0.5" material="mat_hub"/>
            </body>
            <body name="rear_right_wheel_module" pos="-0.43 -0.42 -0.05">
              <geom size="0.07 0.03 0.085" pos="0 0.045 0.04" type="box" mass="0.8" material="mat_column"/>
              <geom size="0.13 0.055" quat="0.707105 0.707108 0 0" type="cylinder" mass="2.5" material="mat_rubber"/>
              <geom size="0.065 0.06" quat="0.707105 0.707108 0 0" type="cylinder" mass="0.5" material="mat_hub"/>
            </body>
          </body>
          <body name="base_z_body">
            <inertial pos="0 0 0.55" mass="10" diaginertia="0.6 0.6 0.4"/>
            <joint name="base_z" pos="0 0 0" axis="0 0 1" type="slide" range="0 0.5" damping="10"/>
            <geom size="0.075 0.145 0.045" pos="-0.12 0 0.635" type="box" mass="0" material="mat_accent"/>
            <geom size="0.34 0.055 0.045" pos="0.1 0.46 0.52" type="box" mass="0" material="mat_aluminum"/>
            <geom size="0.34 0.055 0.045" pos="0.1 -0.46 0.52" type="box" mass="0" material="mat_aluminum"/>
            <geom size="0.065 0.33 0.035" pos="0.14 0 0.515" type="box" mass="0" material="mat_aluminum"/>
            <body name="left_shoulder_mount" pos="0.18 0.46 0.52">
              <inertial pos="0 0 0.035" mass="5" diaginertia="0.1 0.1 0.08"/>
              <geom size="0.09 0.025" type="cylinder" mass="0" material="mat_aluminum"/>
              <geom size="0.075 0.055" pos="0 0 0.06" type="cylinder" mass="0" material="mat_left_arm"/>
              <body name="left_ur5e_base" childclass="ur5e" pos="0 0 0.095" quat="-0.707107 0 0 -0.707107">
                <inertial pos="0 0 0" mass="4" diaginertia="0.00443333 0.00443333 0.0072"/>
                <geom class="visual" material="black" mesh="base_0"/>
                <geom class="visual" material="jointgray" mesh="base_1"/>
                <body name="left_shoulder_link" pos="0 0 0.163">
                  <inertial pos="0 0 0" mass="3.7" diaginertia="0.0102675 0.0102675 0.00666"/>
                  <joint name="left_shoulder_pan_joint" class="size3" pos="0 0 0" axis="0 0 1"/>
                  <geom class="visual" material="urblue" mesh="shoulder_0"/>
                  <geom class="visual" material="black" mesh="shoulder_1"/>
                  <geom class="visual" material="jointgray" mesh="shoulder_2"/>
                  <geom class="collision" size="0.06 0.06" pos="0 0 -0.04"/>
                  <body name="left_upper_arm_link" pos="0 0.138 0" quat="0.707107 0 0.707107 0">
                    <inertial pos="0 0 0.2125" mass="8.393" diaginertia="0.133886 0.133886 0.0151074"/>
                    <joint name="left_shoulder_lift_joint" class="size3" pos="0 0 0" axis="0 1 0"/>
                    <geom class="visual" material="linkgray" mesh="upperarm_0"/>
                    <geom class="visual" material="black" mesh="upperarm_1"/>
                    <geom class="visual" material="jointgray" mesh="upperarm_2"/>
                    <geom class="visual" material="urblue" mesh="upperarm_3"/>
                    <geom class="collision" size="0.06 0.06" pos="0 -0.04 0" quat="0.707107 0.707107 0 0"/>
                    <geom class="collision" size="0.05 0.2" pos="0 0 0.2"/>
                    <body name="left_forearm_link" pos="0 -0.131 0.425">
                      <inertial pos="0 0 0.196" mass="2.275" diaginertia="0.0311796 0.0311796 0.004095"/>
                      <joint name="left_elbow_joint" class="size3_limited" pos="0 0 0" axis="0 1 0"/>
                      <geom class="visual" material="urblue" mesh="forearm_0"/>
                      <geom class="visual" material="linkgray" mesh="forearm_1"/>
                      <geom class="visual" material="black" mesh="forearm_2"/>
                      <geom class="visual" material="jointgray" mesh="forearm_3"/>
                      <geom class="collision" size="0.055 0.06" pos="0 0.08 0" quat="0.707107 0.707107 0 0"/>
                      <geom class="collision" size="0.038 0.19" pos="0 0 0.2"/>
                      <body name="left_wrist_1_link" pos="0 0 0.392" quat="0.707107 0 0.707107 0">
                        <inertial pos="0 0.127 0" mass="1.219" diaginertia="0.0025599 0.0025599 0.0021942"/>
                        <joint name="left_wrist_1_joint" class="size1" pos="0 0 0" axis="0 1 0"/>
                        <geom class="visual" material="black" mesh="wrist1_0"/>
                        <geom class="visual" material="urblue" mesh="wrist1_1"/>
                        <geom class="visual" material="jointgray" mesh="wrist1_2"/>
                        <geom class="collision" size="0.04 0.07" pos="0 0.05 0" quat="0.707107 0.707107 0 0"/>
                        <body name="left_wrist_2_link" pos="0 0.127 0">
                          <inertial pos="0 0 0.1" mass="1.219" diaginertia="0.0025599 0.0025599 0.0021942"/>
                          <joint name="left_wrist_2_joint" class="size1" pos="0 0 0" axis="0 0 1"/>
                          <geom class="visual" material="black" mesh="wrist2_0"/>
                          <geom class="visual" material="urblue" mesh="wrist2_1"/>
                          <geom class="visual" material="jointgray" mesh="wrist2_2"/>
                          <geom class="collision" size="0.04 0.06" pos="0 0 0.04"/>
                          <geom class="collision" size="0.04 0.04" pos="0 0.02 0.1" quat="0.707107 0.707107 0 0"/>
                          <body name="left_wrist_3_link" pos="0 0 0.1">
                            <inertial pos="0 0.0771683 0" quat="0.707107 0 0 0.707107" mass="0.1889" diaginertia="0.000132134 9.90863e-05 9.90863e-05"/>
                            <joint name="left_wrist_3_joint" class="size1" pos="0 0 0" axis="0 1 0"/>
                            <geom class="visual" material="linkgray" mesh="wrist3"/>
                            <geom class="eef_collision" size="0.04 0.02" pos="0 0.08 0" quat="0.707107 0.707107 0 0"/>
                            <site name="left_ee_site" pos="0 0.1 0" quat="-0.707107 0.707107 0 0" size="0.022" rgba="0 1 0 1"/>
                          </body>
                        </body>
                      </body>
                    </body>
                  </body>
                </body>
              </body>
            </body>
            <body name="right_shoulder_mount" pos="0.18 -0.46 0.52">
              <inertial pos="0 0 0.035" mass="5" diaginertia="0.1 0.1 0.08"/>
              <geom size="0.09 0.025" type="cylinder" mass="0" material="mat_aluminum"/>
              <geom size="0.075 0.055" pos="0 0 0.06" type="cylinder" mass="0" material="mat_right_arm"/>
              <body name="right_ur5e_base" childclass="ur5e" pos="0 0 0.095" quat="0.707107 0 0 -0.707107">
                <inertial pos="0 0 0" mass="4" diaginertia="0.00443333 0.00443333 0.0072"/>
                <geom class="visual" material="black" mesh="base_0"/>
                <geom class="visual" material="jointgray" mesh="base_1"/>
                <body name="right_shoulder_link" pos="0 0 0.163">
                  <inertial pos="0 0 0" mass="3.7" diaginertia="0.0102675 0.0102675 0.00666"/>
                  <joint name="right_shoulder_pan_joint" class="size3" pos="0 0 0" axis="0 0 1"/>
                  <geom class="visual" material="urblue" mesh="shoulder_0"/>
                  <geom class="visual" material="black" mesh="shoulder_1"/>
                  <geom class="visual" material="jointgray" mesh="shoulder_2"/>
                  <geom class="collision" size="0.06 0.06" pos="0 0 -0.04"/>
                  <body name="right_upper_arm_link" pos="0 0.138 0" quat="0.707107 0 0.707107 0">
                    <inertial pos="0 0 0.2125" mass="8.393" diaginertia="0.133886 0.133886 0.0151074"/>
                    <joint name="right_shoulder_lift_joint" class="size3" pos="0 0 0" axis="0 1 0"/>
                    <geom class="visual" material="linkgray" mesh="upperarm_0"/>
                    <geom class="visual" material="black" mesh="upperarm_1"/>
                    <geom class="visual" material="jointgray" mesh="upperarm_2"/>
                    <geom class="visual" material="urblue" mesh="upperarm_3"/>
                    <geom class="collision" size="0.06 0.06" pos="0 -0.04 0" quat="0.707107 0.707107 0 0"/>
                    <geom class="collision" size="0.05 0.2" pos="0 0 0.2"/>
                    <body name="right_forearm_link" pos="0 -0.131 0.425">
                      <inertial pos="0 0 0.196" mass="2.275" diaginertia="0.0311796 0.0311796 0.004095"/>
                      <joint name="right_elbow_joint" class="size3_limited" pos="0 0 0" axis="0 1 0"/>
                      <geom class="visual" material="urblue" mesh="forearm_0"/>
                      <geom class="visual" material="linkgray" mesh="forearm_1"/>
                      <geom class="visual" material="black" mesh="forearm_2"/>
                      <geom class="visual" material="jointgray" mesh="forearm_3"/>
                      <geom class="collision" size="0.055 0.06" pos="0 0.08 0" quat="0.707107 0.707107 0 0"/>
                      <geom class="collision" size="0.038 0.19" pos="0 0 0.2"/>
                      <body name="right_wrist_1_link" pos="0 0 0.392" quat="0.707107 0 0.707107 0">
                        <inertial pos="0 0.127 0" mass="1.219" diaginertia="0.0025599 0.0025599 0.0021942"/>
                        <joint name="right_wrist_1_joint" class="size1" pos="0 0 0" axis="0 1 0"/>
                        <geom class="visual" material="black" mesh="wrist1_0"/>
                        <geom class="visual" material="urblue" mesh="wrist1_1"/>
                        <geom class="visual" material="jointgray" mesh="wrist1_2"/>
                        <geom class="collision" size="0.04 0.07" pos="0 0.05 0" quat="0.707107 0.707107 0 0"/>
                        <body name="right_wrist_2_link" pos="0 0.127 0">
                          <inertial pos="0 0 0.1" mass="1.219" diaginertia="0.0025599 0.0025599 0.0021942"/>
                          <joint name="right_wrist_2_joint" class="size1" pos="0 0 0" axis="0 0 1"/>
                          <geom class="visual" material="black" mesh="wrist2_0"/>
                          <geom class="visual" material="urblue" mesh="wrist2_1"/>
                          <geom class="visual" material="jointgray" mesh="wrist2_2"/>
                          <geom class="collision" size="0.04 0.06" pos="0 0 0.04"/>
                          <geom class="collision" size="0.04 0.04" pos="0 0.02 0.1" quat="0.707107 0.707107 0 0"/>
                          <body name="right_wrist_3_link" pos="0 0 0.1">
                            <inertial pos="0 0.0771683 0" quat="0.707107 0 0 0.707107" mass="0.1889" diaginertia="0.000132134 9.90863e-05 9.90863e-05"/>
                            <joint name="right_wrist_3_joint" class="size1" pos="0 0 0" axis="0 1 0"/>
                            <geom class="visual" material="linkgray" mesh="wrist3"/>
                            <geom class="eef_collision" size="0.04 0.02" pos="0 0.08 0" quat="0.707107 0.707107 0 0"/>
                            <site name="right_ee_site" pos="0 0.1 0" quat="-0.707107 0.707107 0 0" size="0.022" rgba="0 0.85 1 1"/>
                          </body>
                        </body>
                      </body>
                    </body>
                  </body>
                </body>
              </body>
            </body>
          </body>
        </body>
      </body>
    </body>
  </worldbody>

  <actuator>
    <general name="act_base_x" joint="base_x" ctrlrange="-3 3" gainprm="2000" biasprm="0 -2000 -200"/>
    <general name="act_base_y" joint="base_y" ctrlrange="-3 3" gainprm="2000" biasprm="0 -2000 -200"/>
    <general name="act_base_z" joint="base_z" ctrlrange="0 0.5" gainprm="35000" biasprm="0 -35000 -800"/>
    <general name="act_base_yaw" joint="base_yaw" ctrlrange="-3.1416 3.1416" gainprm="2000" biasprm="0 -2000 -200"/>
    <general name="act_left_shoulder_pan" joint="left_shoulder_pan_joint" ctrlrange="-6.28 6.28" gainprm="2600" biasprm="0 -2600 -190"/>
    <general name="act_left_shoulder_lift" joint="left_shoulder_lift_joint" ctrlrange="-6.28 6.28" gainprm="2600" biasprm="0 -2600 -190"/>
    <general name="act_left_elbow" joint="left_elbow_joint" ctrlrange="-3.14 3.14" gainprm="2200" biasprm="0 -2200 -160"/>
    <general name="act_left_wrist_1" joint="left_wrist_1_joint" ctrlrange="-6.28 6.28" gainprm="600" biasprm="0 -600 -60"/>
    <general name="act_left_wrist_2" joint="left_wrist_2_joint" ctrlrange="-6.28 6.28" gainprm="600" biasprm="0 -600 -60"/>
    <general name="act_left_wrist_3" joint="left_wrist_3_joint" ctrlrange="-6.28 6.28" gainprm="600" biasprm="0 -600 -60"/>
    <general name="act_right_shoulder_pan" joint="right_shoulder_pan_joint" ctrlrange="-6.28 6.28" gainprm="2600" biasprm="0 -2600 -190"/>
    <general name="act_right_shoulder_lift" joint="right_shoulder_lift_joint" ctrlrange="-6.28 6.28" gainprm="2600" biasprm="0 -2600 -190"/>
    <general name="act_right_elbow" joint="right_elbow_joint" ctrlrange="-3.14 3.14" gainprm="2200" biasprm="0 -2200 -160"/>
    <general name="act_right_wrist_1" joint="right_wrist_1_joint" ctrlrange="-6.28 6.28" gainprm="600" biasprm="0 -600 -60"/>
    <general name="act_right_wrist_2" joint="right_wrist_2_joint" ctrlrange="-6.28 6.28" gainprm="600" biasprm="0 -600 -60"/>
    <general name="act_right_wrist_3" joint="right_wrist_3_joint" ctrlrange="-6.28 6.28" gainprm="600" biasprm="0 -600 -60"/>
  </actuator>

  <keyframe>
    <key name="home" qpos="0 0 0 0.2 0 -1.2 1.6 -0.4 -1.5708 0 0 -1.2 1.6 -0.4 -1.5708 0" ctrl="0 0 0.2 0 0 -1.2 1.6 -0.4 -1.5708 0 0 -1.2 1.6 -0.4 -1.5708 0"/>
  </keyframe>
</mujoco>
